Workbook

Sheet Dashboard
A1: Big Bear Vacations Dashboard
A2: Fiscal Year (Apr–Mar) — use the View Scope selector (cell C3) to switch between full-year and a single month; KPIs, Top-10 profit tables, and the expense category chart all follow it
B3: View Scope: | C3: All (Fiscal Year) | D3: TOTAL REVENUE | G3: TOTAL EXPENSES | J3: TOTAL PROFIT
D4: =IF($C$3="All (Fiscal Year)",SUM(CalcTbl[Total Revenue]),SUMIFS(CalcTbl[Total Revenue],CalcTbl[Month],$C$3)) -> 8849999.5 | G4: =IF($C$3="All (Fiscal Year)",SUM(CalcTbl[Total Expenses]),SUMIFS(CalcTbl[Total Expenses],CalcTbl[Month],$C$3)) -> 4017935.9 | J4: =D4-G4 -> 4832063.5
B20: Top 10 Best Properties by Profit | F20: Top 10 Worst Properties by Profit | J20: Top 10 Best Properties by Guest Rating | N20: Top 10 Worst Properties by Guest Rating
B21: Rank | C21: Best Property | D21: Profit | F21: Rank | G21: Worst Property | H21: Profit | J21: Rank | K21: Best Property | L21: Rating | N21: Rank | O21: Worst Property | P21: Rating
B22: =ROW()-21 -> 1 | C22: {=INDEX(Calc!$X$4:$X$13,$B22)} -> Alpine Cottage | D22: {=INDEX(Calc!$Y$4:$Y$13,$B22)} -> 64476.618 | F22: =322-ROW() -> 300 | G22: {=INDEX(Calc!$Z$4:$Z$13,ROW()-21)} -> Birch Perch | H22: {=INDEX(Calc!$AA$4:$AA$13,ROW()-21)} -> 5146.4967 | J22: =ROW()-21 -> 1 | K22: {=INDEX(Calc!$AB$4:$AB$13,$J22)} -> Snowline Cabin | L22: {=INDEX(Calc!$AC$4:$AC$13,$J22)} -> 5 | N22: =322-ROW() -> 300 | O22: {=INDEX(Calc!$AD$4:$AD$13,ROW()-21)} -> Frost Villa | P22: {=INDEX(Calc!$AE$4:$AE$13,ROW()-21)} -> 2.73
B23: =ROW()-21 -> 2 | C23: {=INDEX(Calc!$X$4:$X$13,$B23)} -> Boulder Cottage | D23: {=INDEX(Calc!$Y$4:$Y$13,$B23)} -> 62149.44 | F23: =322-ROW() -> 299 | G23: {=INDEX(Calc!$Z$4:$Z$13,ROW()-21)} -> Timber Refuge | H23: {=INDEX(Calc!$AA$4:$AA$13,ROW()-21)} -> 5402.758 | J23: =ROW()-21 -> 2 | K23: {=INDEX(Calc!$AB$4:$AB$13,$J23)} -> Bearpaw Villa | L23: {=INDEX(Calc!$AC$4:$AC$13,$J23)} -> 5 | N23: =322-ROW() -> 299 | O23: {=INDEX(Calc!$AD$4:$AD$13,ROW()-21)} -> Lakeview Retreat | P23: {=INDEX(Calc!$AE$4:$AE$13,ROW()-21)} -> 2.7816667
B24: =ROW()-21 -> 3 | C24: {=INDEX(Calc!$X$4:$X$13,$B24)} -> Starlight Hollow | D24: {=INDEX(Calc!$Y$4:$Y$13,$B24)} -> 61412.382 | F24: =322-ROW() -> 298 | G24: {=INDEX(Calc!$Z$4:$Z$13,ROW()-21)} -> Cedar Perch | H24: {=INDEX(Calc!$AA$4:$AA$13,ROW()-21)} -> 5705.8814 | J24: =ROW()-21 -> 3 | K24: {=INDEX(Calc!$AB$4:$AB$13,$J24)} -> Snowline Overlook | L24: {=INDEX(Calc!$AC$4:$AC$13,$J24)} -> 5 | N24: =322-ROW() -> 298 | O24: {=INDEX(Calc!$AD$4:$AD$13,ROW()-21)} -> Cinder Landing | P24: {=INDEX(Calc!$AE$4:$AE$13,ROW()-21)} -> 2.835
B25: =ROW()-21 -> 4 | C25: {=INDEX(Calc!$X$4:$X$13,$B25)} -> Highland Escape | D25: {=INDEX(Calc!$Y$4:$Y$13,$B25)} -> 56125.159 | F25: =322-ROW() -> 297 | G25: {=INDEX(Calc!$Z$4:$Z$13,ROW()-21)} -> Pine Cottage | H25: {=INDEX(Calc!$AA$4:$AA$13,ROW()-21)} -> 5924.0998 | J25: =ROW()-21 -> 4 | K25: {=INDEX(Calc!$AB$4:$AB$13,$J25)} -> Frost Manor | L25: {=INDEX(Calc!$AC$4:$AC$13,$J25)} -> 4.985 | N25: =322-ROW() -> 297 | O25: {=INDEX(Calc!$AD$4:$AD$13,ROW()-21)} -> Highland Escape | P25: {=INDEX(Calc!$AE$4:$AE$13,ROW()-21)} -> 2.8516667
B26: =ROW()-21 -> 5 | C26: {=INDEX(Calc!$X$4:$X$13,$B26)} -> Juniper Escape | D26: {=INDEX(Calc!$Y$4:$Y$13,$B26)} -> 54531.892 | F26: =322-ROW() -> 296 | G26: {=INDEX(Calc!$Z$4:$Z$13,ROW()-21)} -> Bearpaw Landing | H26: {=INDEX(Calc!$AA$4:$AA$13,ROW()-21)} -> 6206.0879 | J26: =ROW()-21 -> 5 | K26: {=INDEX(Calc!$AB$4:$AB$13,$J26)} -> Alpine Haven | L26: {=INDEX(Calc!$AC$4:$AC$13,$J26)} -> 4.9816667 | N26: =322-ROW() -> 296 | O26: {=INDEX(Calc!$AD$4:$AD$13,ROW()-21)} -> Forest Nest | P26: {=INDEX(Calc!$AE$4:$AE$13,ROW()-21)} -> 2.87
B27: =ROW()-21 -> 6 | C27: {=INDEX(Calc!$X$4:$X$13,$B27)} -> Evergreen House | D27: {=INDEX(Calc!$Y$4:$Y$13,$B27)} -> 45232.618 | F27: =322-ROW() -> 295 | G27: {=INDEX(Calc!$Z$4:$Z$13,ROW()-21)} -> Sierra Hideaway | H27: {=INDEX(Calc!$AA$4:$AA$13,ROW()-21)} -> 6282.3273 | J27: =ROW()-21 -> 6 | K27: {=INDEX(Calc!$AB$4:$AB$13,$J27)} -> Bearpaw Hideaway | L27: {=INDEX(Calc!$AC$4:$AC$13,$J27)} -> 4.9783333 | N27: =322-ROW() -> 295 | O27: {=INDEX(Calc!$AD$4:$AD$13,ROW()-21)} -> Timber Landing | P27: {=INDEX(Calc!$AE$4:$AE$13,ROW()-21)} -> 2.9283333
B28: =ROW()-21 -> 7 | C28: {=INDEX(Calc!$X$4:$X$13,$B28)} -> Cloudline Chalet | D28: {=INDEX(Calc!$Y$4:$Y$13,$B28)} -> 41426.595 | F28: =322-ROW() -> 294 | G28: {=INDEX(Calc!$Z$4:$Z$13,ROW()-21)} -> Summit Cottage | H28: {=INDEX(Calc!$AA$4:$AA$13,ROW()-21)} -> 6346.915 | J28: =ROW()-21 -> 7 | K28: {=INDEX(Calc!$AB$4:$AB$13,$J28)} -> Granite Refuge | L28: {=INDEX(Calc!$AC$4:$AC$13,$J28)} -> 4.9733333 | N28: =322-ROW() -> 294 | O28: {=INDEX(Calc!$AD$4:$AD$13,ROW()-21)} -> Bearpaw Point | P28: {=INDEX(Calc!$AE$4:$AE$13,ROW()-21)} -> 2.965
B29: =ROW()-21 -> 8 | C29: {=INDEX(Calc!$X$4:$X$13,$B29)} -> Juniper Cottage | D29: {=INDEX(Calc!$Y$4:$Y$13,$B29)} -> 34516.147 | F29: =322-ROW() -> 293 | G29: {=INDEX(Calc!$Z$4:$Z$13,ROW()-21)} -> Highland Nest | H29: {=INDEX(Calc!$AA$4:$AA$13,ROW()-21)} -> 6485.0543 | J29: =ROW()-21 -> 8 | K29: {=INDEX(Calc!$AB$4:$AB$13,$J29)} -> Copper Nest | L29: {=INDEX(Calc!$AC$4:$AC$13,$J29)} -> 4.9716667 | N29: =322-ROW() -> 293 | O29: {=INDEX(Calc!$AD$4:$AD$13,ROW()-21)} -> Juniper Perch | P29: {=INDEX(Calc!$AE$4:$AE$13,ROW()-21)} -> 2.9916667
B30: =ROW()-21 -> 9 | C30: {=INDEX(Calc!$X$4:$X$13,$B30)} -> Birch Manor | D30: {=INDEX(Calc!$Y$4:$Y$13,$B30)} -> 32408.18 | F30: =322-ROW() -> 292 | G30: {=INDEX(Calc!$Z$4:$Z$13,ROW()-21)} -> Alpine Overlook | H30: {=INDEX(Calc!$AA$4:$AA$13,ROW()-21)} -> 6631.3252 | J30: =ROW()-21 -> 9 | K30: {=INDEX(Calc!$AB$4:$AB$13,$J30)} -> Cloudline Landing | L30: {=INDEX(Calc!$AC$4:$AC$13,$J30)} -> 4.9716667 | N30: =322-ROW() -> 292 | O30: {=INDEX(Calc!$AD$4:$AD$13,ROW()-21)} -> Sierra Retreat | P30: {=INDEX(Calc!$AE$4:$AE$13,ROW()-21)} -> 2.9983333
B31: =ROW()-21 -> 10 | C31: {=INDEX(Calc!$X$4:$X$13,$B31)} -> Mountain Getaway | D31: {=INDEX(Calc!$Y$4:$Y$13,$B31)} -> 32291.495 | F31: =322-ROW() -> 291 | G31: {=INDEX(Calc!$Z$4:$Z$13,ROW()-21)} -> Golden Refuge | H31: {=INDEX(Calc!$AA$4:$AA$13,ROW()-21)} -> 6754.0566 | J31: =ROW()-21 -> 10 | K31: {=INDEX(Calc!$AB$4:$AB$13,$J31)} -> Timber Hollow | L31: {=INDEX(Calc!$AC$4:$AC$13,$J31)} -> 4.9716667 | N31: =322-ROW() -> 291 | O31: {=INDEX(Calc!$AD$4:$AD$13,ROW()-21)} -> Aspen Landing | P31: {=INDEX(Calc!$AE$4:$AE$13,ROW()-21)} -> 3.25
J32: *Note: Ratings do not have any dates associated with them from data, so View Scope will not affect these charts
B33: Secondary KPIs — follow the View Scope selector (C3)
B34: PROFIT MARGIN | E34: AVG NIGHTLY RATE | H34: TOTAL NIGHTS BOOKED | K34: AVG PROFIT / PROPERTY | N34: TOTAL TURNOVERS
B35: =IFERROR(J4/D4,0) -> 0.54599591 | E35: =IFERROR((IF($C$3="All (Fiscal Year)",SUM(RevenueTbl[Gross Booking Revenue]),SUMIFS(RevenueTbl[Gross Booking Revenue],RevenueTbl[Month],$C$3)))/H35,0) -> 231.0879 | H35: =IF($C$3="All (Fiscal Year)",SUM(RevenueTbl[Nights Booked]),SUMIFS(RevenueTbl[Nights Booked],RevenueTbl[Month],$C$3)) -> 31969 | K35: =J4/COUNTA(PropertiesTbl[Property ID]) -> 16106.878 | N35: =IF($C$3="All (Fiscal Year)",SUM(RevenueTbl[Turnovers]),SUMIFS(RevenueTbl[Turnovers],RevenueTbl[Month],$C$3)) -> 10887

Sheet Properties
A1: Property Master List
A2: Blue cells are sample portfolio data — 300 properties, max occupancy capped at 16 guests (Big Bear's local max). Unchanged from the prior version.
A4: Property ID | B4: Property Name | C4: Neighborhood | D4: Property Type | E4: Bedrooms | F4: Max Guests | G4: Base Nightly Rate
A5: P0001 | B5: Snowline Hideaway | C5: Baldwin Lake | D5: Lodge | E5: 1 | F5: 5 | G5: 187
A6: P0002 | B6: Meadow Lodge | C6: Sugarloaf | D6: Cabin | E6: 4 | F6: 9 | G6: 370
A7: P0003 | B7: Alpine Perch | C7: Baldwin Lake | D7: Cabin | E7: 3 | F7: 6 | G7: 287
A8: P0004 | B8: Lakeview Villa | C8: Eagle Point | D8: Cabin | E8: 4 | F8: 11 | G8: 389
A9: P0005 | B9: Evergreen Lodge | C9: Fawnskin | D9: Cabin | E9: 6 | F9: 12 | G9: 549
A10: P0006 | B10: Granite Landing | C10: Gold Mountain | D10: Cabin | E10: 3 | F10: 6 | G10: 286
A11: P0007 | B11: Bearpaw Lodge | C11: Fawnskin | D11: Condo | E11: 3 | F11: 7 | G11: 287
A12: P0008 | B12: Alpine Overlook | C12: Erwin Lake | D12: Cabin | E12: 1 | F12: 4 | G12: 147
A13: P0009 | B13: Ridge Cabin | C13: Gold Mountain | D13: Lodge | E13: 2 | F13: 6 | G13: 256
A14: P0010 | B14: Aspen Cabin | C14: Fox Farm | D14: Cabin | E14: 3 | F14: 7 | G14: 305
A15: P0011 | B15: Frost Overlook | C15: Big Bear City | D15: Chalet | E15: 4 | F15: 8 | G15: 414
A16: P0012 | B16: Cedar Den | C16: Fox Farm | D16: Condo | E16: 4 | F16: 10 | G16: 371
... A304: P0300 | B304: Trailside Cottage | C304: Sugarloaf | D304: Cabin | E304: 4 | F304: 9 | G304: 372

Sheet Revenue
A1: Revenue Report
A2: Rows run in fiscal-year order (Apr -> Mar) per property. Blue = actual booking data (input). Black = same-sheet formulas. Property Name/Bedrooms/Neighborhood are intentionally NOT included — pull them with XLOOKUP/INDEX-MATCH against the Properties tab.
A4: Property ID | B4: Month | C4: Nights Booked | D4: Avg Nightly Rate | E4: Gross Booking Revenue | F4: Airbnb Host Fee % | G4: Airbnb Host Fee $ | H4: Turnovers | I4: Cleaning Fee Collected | J4: Total Revenue | K4: Key
A5: P0001 | B5: Apr | C5: 6 | D5: 99.38 | E5: =C5*D5 -> 596.28 | F5: 0.03 | G5: =E5*F5 -> 17.8884 | H5: 2 | I5: 190 | J5: =E5+I5-G5 -> 768.3916 | K5: =A5&"|"&B5 -> P0001|Apr
A6: P0001 | B6: May | C6: 7 | D6: 107.63 | E6: =C6*D6 -> 753.41 | F6: 0.03 | G6: =E6*F6 -> 22.6023 | H6: 2 | I6: 190 | J6: =E6+I6-G6 -> 920.8077 | K6: =A6&"|"&B6 -> P0001|May
A7: P0001 | B7: Jun | C7: 8 | D7: 105.32 | E7: =C7*D7 -> 842.56 | F7: 0.03 | G7: =E7*F7 -> 25.2768 | H7: 2 | I7: 190 | J7: =E7+I7-G7 -> 1007.2832 | K7: =A7&"|"&B7 -> P0001|Jun
A8: P0001 | B8: Jul | C8: 11 | D8: 114.19 | E8: =C8*D8 -> 1256.09 | F8: 0.03 | G8: =E8*F8 -> 37.6827 | H8: 3 | I8: 285 | J8: =E8+I8-G8 -> 1503.4073 | K8: =A8&"|"&B8 -> P0001|Jul
A9: P0001 | B9: Aug | C9: 11 | D9: 116.02 | E9: =C9*D9 -> 1276.22 | F9: 0.03 | G9: =E9*F9 -> 38.2866 | H9: 3 | I9: 285 | J9: =E9+I9-G9 -> 1522.9334 | K9: =A9&"|"&B9 -> P0001|Aug
A10: P0001 | B10: Sep | C10: 7 | D10: 100.29 | E10: =C10*D10 -> 702.03 | F10: 0.03 | G10: =E10*F10 -> 21.0609 | H10: 2 | I10: 190 | J10: =E10+I10-G10 -> 870.9691 | K10: =A10&"|"&B10 -> P0001|Sep
A11: P0001 | B11: Oct | C11: 7 | D11: 90.66 | E11: =C11*D11 -> 634.62 | F11: 0.03 | G11: =E11*F11 -> 19.0386 | H11: 2 | I11: 190 | J11: =E11+I11-G11 -> 805.5814 | K11: =A11&"|"&B11 -> P0001|Oct
A12: P0001 | B12: Nov | C12: 6 | D12: 108.14 | E12: =C12*D12 -> 648.84 | F12: 0.03 | G12: =E12*F12 -> 19.4652 | H12: 2 | I12: 190 | J12: =E12+I12-G12 -> 819.3748 | K12: =A12&"|"&B12 -> P0001|Nov
A13: P0001 | B13: Dec | C13: 15 | D13: 186.44 | E13: =C13*D13 -> 2796.6 | F13: 0.03 | G13: =E13*F13 -> 83.898 | H13: 6 | I13: 570 | J13: =E13+I13-G13 -> 3282.702 | K13: =A13&"|"&B13 -> P0001|Dec
A14: P0001 | B14: Jan | C14: 14 | D14: 167.2 | E14: =C14*D14 -> 2340.8 | F14: 0.03 | G14: =E14*F14 -> 70.224 | H14: 5 | I14: 475 | J14: =E14+I14-G14 -> 2745.576 | K14: =A14&"|"&B14 -> P0001|Jan
A15: P0001 | B15: Feb | C15: 12 | D15: 155.66 | E15: =C15*D15 -> 1867.92 | F15: 0.03 | G15: =E15*F15 -> 56.0376 | H15: 5 | I15: 475 | J15: =E15+I15-G15 -> 2286.8824 | K15: =A15&"|"&B15 -> P0001|Feb
A16: P0001 | B16: Mar | C16: 12 | D16: 132.25 | E16: =C16*D16 -> 1587 | F16: 0.03 | G16: =E16*F16 -> 47.61 | H16: 4 | I16: 380 | J16: =E16+I16-G16 -> 1919.39 | K16: =A16&"|"&B16 -> P0001|Mar
... A3604: P0300 | B3604: Mar | C3604: 12 | D3604: 269.89 | E3604: =C3604*D3604 -> 3238.68 | F3604: 0.03 | G3604: =E3604*F3604 -> 97.1604 | H3604: 4 | I3604: 740 | J3604: =E3604+I3604-G3604 -> 3881.5196 | K3604: =A3604&"|"&B3604 -> P0300|Mar

Sheet Expenses
A1: Operating Expenses Report
A2: Rows run in fiscal-year order (Apr -> Mar) per property. Blue = actual expense data (input). Black = same-sheet formulas. 'Seasonal Operations & Marketing' is the line that flexes to keep every off-season month a controlled loss (none exceeding $300k).
A4: Property ID | B4: Month | C4: Maintenance & Repairs | D4: Supplies & Restocking | E4: Housekeeping Cost | F4: Snow Removal & Winter Prep | G4: Management & Software Overhead | H4: Seasonal Operations & Marketing | I4: Total Operating Expenses | J4: Key
A5: P0001 | B5: Apr | C5: 15.882278 | D5: 4.04 | E5: 293.72772 | F5: 0 | G5: 85.96 | H5: 19.87 | I5: =SUM(C5:H5) -> 419.48 | J5: =A5&"|"&B5 -> P0001|Apr
A6: P0001 | B6: May | C6: 15.356476 | D6: 4.04 | E6: 284.00352 | F6: 0 | G6: 85.96 | H6: 129.25 | I6: =SUM(C6:H6) -> 518.61 | J6: =A6&"|"&B6 -> P0001|May
A7: P0001 | B7: Jun | C7: 14.944043 | D7: 4.04 | E7: 276.37596 | F7: 0 | G7: 85.96 | H7: 167.46 | I7: =SUM(C7:H7) -> 548.78 | J7: =A7&"|"&B7 -> P0001|Jun
A8: P0001 | B8: Jul | C8: 12.536758 | D8: 7.7 | E8: 347.78324 | F8: 0 | G8: 85.96 | H8: 448.89 | I8: =SUM(C8:H8) -> 902.87 | J8: =A8&"|"&B8 -> P0001|Jul
A9: P0001 | B9: Aug | C9: 27.277926 | D9: 4.04 | E9: 334.99207 | F9: 0 | G9: 85.96 | H9: 414.07 | I9: =SUM(C9:H9) -> 866.34 | J9: =A9&"|"&B9 -> P0001|Aug
A10: P0001 | B10: Sep | C10: 30.10903 | D10: 6.23 | E10: 260.04097 | F10: 0 | G10: 85.96 | H10: 88.65 | I10: =SUM(C10:H10) -> 470.99 | J10: =A10&"|"&B10 -> P0001|Sep
A11: P0001 | B11: Oct | C11: 386.61032 | D11: 9.55 | E11: 188.22968 | F11: 0 | G11: 85.96 | H11: 61.32 | I11: =SUM(C11:H11) -> 731.67 | J11: =A11&"|"&B11 -> P0001|Oct
A12: P0001 | B12: Nov | C12: 13.61894 | D12: 4.04 | E12: 251.86943 | F12: 81.73163 | G12: 85.96 | H12: 15.82 | I12: =SUM(C12:H12) -> 453.04 | J12: =A12&"|"&B12 -> P0001|Nov
A13: P0001 | B13: Dec | C13: 10.135318 | D13: 4.04 | E13: 562.32939 | F13: 60.825295 | G13: 85.96 | H13: 27.92 | I13: =SUM(C13:H13) -> 751.21 | J13: =A13&"|"&B13 -> P0001|Dec
A14: P0001 | B14: Jan | C14: 11.463163 | D14: 4.04 | E14: 500.26273 | F14: 64.934103 | G14: 85.96 | H14: 27.92 | I14: =SUM(C14:H14) -> 694.58 | J14: =A14&"|"&B14 -> P0001|Jan
A15: P0001 | B15: Feb | C15: 10.845387 | D15: 4.04 | E15: 501.43797 | F15: 65.086648 | G15: 85.96 | H15: 27.92 | I15: =SUM(C15:H15) -> 695.29 | J15: =A15&"|"&B15 -> P0001|Feb
A16: P0001 | B16: Mar | C16: 11.128127 | D16: 4.04 | E16: 411.60841 | F16: 66.783464 | G16: 85.96 | H16: 27.92 | I16: =SUM(C16:H16) -> 607.44 | J16: =A16&"|"&B16 -> P0001|Mar
... A3604: P0300 | B3604: Mar | C3604: 22.98412 | D3604: 8.17 | E3604: 803.68313 | F3604: 126.76275 | G3604: 85.96 | H3604: 111.67 | I3604: =SUM(C3604:H3604) -> 1159.23 | J3604: =A3604&"|"&B3604 -> P0300|Mar

Sheet Ratings
A1: Guest Ratings Report
A2: Blue = actual review data (input). Overall Rating is calculated as the average of the six Airbnb category scores. Unchanged from the prior version — portfolio average ~4.8, with real spread (some properties below 3.0).
A4: Property ID | B4: Total Reviews | C4: Cleanliness | D4: Communication | E4: Check-in | F4: Accuracy | G4: Location | H4: Value | I4: Overall Rating
A5: P0001 | B5: 88 | C5: 4.92 | D5: 4.98 | E5: 5 | F5: 4.9 | G5: 4.95 | H5: 4.89 | I5: =AVERAGE(C5:H5) -> 4.94
A6: P0002 | B6: 97 | C6: 4.99 | D6: 4.8 | E6: 4.92 | F6: 4.91 | G6: 4.96 | H6: 4.93 | I6: =AVERAGE(C6:H6) -> 4.9183333
A7: P0003 | B7: 26 | C7: 3.7 | D7: 3.04 | E7: 3.43 | F7: 4.44 | G7: 3.48 | H7: 3.26 | I7: =AVERAGE(C7:H7) -> 3.5583333
A8: P0004 | B8: 107 | C8: 5 | D8: 4.93 | E8: 4.99 | F8: 4.97 | G8: 4.96 | H8: 4.89 | I8: =AVERAGE(C8:H8) -> 4.9566667
A9: P0005 | B9: 178 | C9: 4.89 | D9: 4.95 | E9: 5 | F9: 4.95 | G9: 4.84 | H9: 4.99 | I9: =AVERAGE(C9:H9) -> 4.9366667
A10: P0006 | B10: 8 | C10: 4.9 | D10: 5 | E10: 5 | F10: 4.9 | G10: 5 | H10: 4.9 | I10: =AVERAGE(C10:H10) -> 4.95
A11: P0007 | B11: 149 | C11: 4.93 | D11: 4.93 | E11: 4.88 | F11: 4.88 | G11: 4.99 | H11: 5 | I11: =AVERAGE(C11:H11) -> 4.935
A12: P0008 | B12: 38 | C12: 4.88 | D12: 4.89 | E12: 4.9 | F12: 4.98 | G12: 4.98 | H12: 4.96 | I12: =AVERAGE(C12:H12) -> 4.9316667
A13: P0009 | B13: 141 | C13: 4.89 | D13: 4.92 | E13: 4.96 | F13: 4.97 | G13: 4.92 | H13: 4.95 | I13: =AVERAGE(C13:H13) -> 4.935
A14: P0010 | B14: 8 | C14: 4.93 | D14: 4.92 | E14: 4.9 | F14: 5 | G14: 4.89 | H14: 4.96 | I14: =AVERAGE(C14:H14) -> 4.9333333
A15: P0011 | B15: 134 | C15: 4.95 | D15: 4.98 | E15: 4.98 | F15: 5 | G15: 4.94 | H15: 4.96 | I15: =AVERAGE(C15:H15) -> 4.9683333
A16: P0012 | B16: 113 | C16: 4.93 | D16: 4.95 | E16: 4.86 | F16: 4.94 | G16: 4.93 | H16: 4.92 | I16: =AVERAGE(C16:H16) -> 4.9216667
... A304: P0300 | B304: 83 | C304: 4.93 | D304: 4.89 | E304: 5 | F304: 5 | G304: 4.9 | H304: 5 | I304: =AVERAGE(C304:H304) -> 4.9533333

Sheet Calc
A1: Property x Month Calculation Table | I1: Monthly Trend (Full Year) | N1: Property Annual Totals | W1: Top 10 Rankings (INDEX/MATCH) | AJ1: Expense Category Breakdown
A3: Property ID | B3: Month | C3: Key | D3: Total Revenue | E3: Total Expenses | F3: Profit | G3: Property Name | I3: Month | J3: Total Revenue | K3: Total Expenses | L3: Profit | N3: Property ID | O3: Property Name | P3: Total Revenue | Q3: Total Expenses | R3: Total Profit | S3: Overall Rating | T3: Profit Rank | U3: Rating Rank | W3: Rank | X3: Best Property (Profit) | Y3: Profit | Z3: Worst Property (Profit) | AA3: Profit | AB3: Best Property (Rating) | AC3: Rating | AD3: Worst Property (Rating) | AE3: Rating | AG3: Profit (tiebreak) | AH3: Rating (tiebreak) | AJ3: Expense Category | AK3: Total ($)
A4: =Revenue!A5 -> P0001 | B4: =Revenue!B5 -> Apr | C4: =A4&"|"&B4 -> P0001|Apr | D4: =Revenue!J5 -> 768.3916 | E4: =_xlfn.XLOOKUP($C4,ExpensesTbl[Key],ExpensesTbl[Total Operating Expenses]) -> 419.48 | F4: =D4-E4 -> 348.9116 | G4: =_xlfn.XLOOKUP($A4,PropertiesTbl[Property ID],PropertiesTbl[Property Name]) -> Snowline Hideaway | I4: Apr | J4: =SUMIFS(CalcTbl[Total Revenue],CalcTbl[Month],$I4) -> 353570.34 | K4: =SUMIFS(CalcTbl[Total Expenses],CalcTbl[Month],$I4) -> 198004.26 | L4: =J4-K4 -> 155566.08 | N4: =Properties!A5 -> P0001 | O4: =_xlfn.XLOOKUP($N4,PropertiesTbl[Property ID],PropertiesTbl[Property Name]) -> Snowline Hideaway | P4: =SUMIFS(CalcTbl[Total Revenue],CalcTbl[Property ID],$N4,CalcTbl[Month],IF(Dashboard!$C$3="All (Fiscal Year)","*",Dashboard!$C$3)) -> 18453.299 | Q4: =SUMIFS(CalcTbl[Total Expenses],CalcTbl[Property ID],$N4,CalcTbl[Month],IF(Dashboard!$C$3="All (Fiscal Year)","*",Dashboard!$C$3)) -> 7660.3 | R4: =P4-Q4 -> 10792.999 | S4: =_xlfn.XLOOKUP($N4,RatingsTbl[Property ID],RatingsTbl[Overall Rating]) -> 4.94 | T4: =_xlfn.RANK.EQ(AG4,$AG$4:$AG$303,0) -> 221 | U4: =_xlfn.RANK.EQ(AH4,$AH$4:$AH$303,0) -> 111 | W4: =ROW()-3 -> 1 | X4: =INDEX($O$4:$O$303,MATCH($W4,$T$4:$T$303,0)) -> Alpine Cottage | Y4: =INDEX($R$4:$R$303,MATCH($W4,$T$4:$T$303,0)) -> 64476.618 | Z4: =INDEX($O$4:$O$303,MATCH(301-$W4,$T$4:$T$303,0)) -> Birch Perch | AA4: =INDEX($R$4:$R$303,MATCH(301-$W4,$T$4:$T$303,0)) -> 5146.4967 | AB4: =INDEX($O$4:$O$303,MATCH($W4,$U$4:$U$303,0)) -> Snowline Cabin | AC4: =INDEX($S$4:$S$303,MATCH($W4,$U$4:$U$303,0)) -> 5 | AD4: =INDEX($O$4:$O$303,MATCH(301-$W4,$U$4:$U$303,0)) -> Frost Villa | AE4: =INDEX($S$4:$S$303,MATCH(301-$W4,$U$4:$U$303,0)) -> 2.73 | AG4: =R4+(ROW()-3)*0.0000001 -> 10792.999 | AH4: =S4+(ROW()-3)*0.0000001 -> 4.9400001 | AJ4: Maintenance & Repairs | AK4: =IF(Dashboard!$C$3="All (Fiscal Year)",SUM(ExpensesTbl[Maintenance & Repairs]),SUMIFS(ExpensesTbl[Maintenance & Repairs],ExpensesTbl[Month],Dashboard!$C$3)) -> 176708.23
A5: =Revenue!A6 -> P0001 | B5: =Revenue!B6 -> May | C5: =A5&"|"&B5 -> P0001|May | D5: =Revenue!J6 -> 920.8077 | E5: =_xlfn.XLOOKUP($C5,ExpensesTbl[Key],ExpensesTbl[Total Operating Expenses]) -> 518.61 | F5: =D5-E5 -> 402.1977 | G5: =_xlfn.XLOOKUP($A5,PropertiesTbl[Property ID],PropertiesTbl[Property Name]) -> Snowline Hideaway | I5: May | J5: =SUMIFS(CalcTbl[Total Revenue],CalcTbl[Month],$I5) -> 420962.7 | K5: =SUMIFS(CalcTbl[Total Expenses],CalcTbl[Month],$I5) -> 295953.6 | L5: =J5-K5 -> 125009.1 | N5: =Properties!A6 -> P0002 | O5: =_xlfn.XLOOKUP($N5,PropertiesTbl[Property ID],PropertiesTbl[Property Name]) -> Meadow Lodge | P5: =SUMIFS(CalcTbl[Total Revenue],CalcTbl[Property ID],$N5,CalcTbl[Month],IF(Dashboard!$C$3="All (Fiscal Year)","*",Dashboard!$C$3)) -> 31721.315 | Q5: =SUMIFS(CalcTbl[Total Expenses],CalcTbl[Property ID],$N5,CalcTbl[Month],IF(Dashboard!$C$3="All (Fiscal Year)","*",Dashboard!$C$3)) -> 16004.02 | R5: =P5-Q5 -> 15717.294 | S5: =_xlfn.XLOOKUP($N5,RatingsTbl[Property ID],RatingsTbl[Overall Rating]) -> 4.9183333 | T5: =_xlfn.RANK.EQ(AG5,$AG$4:$AG$303,0) -> 117 | U5: =_xlfn.RANK.EQ(AH5,$AH$4:$AH$303,0) -> 209 | W5: =ROW()-3 -> 2 | X5: =INDEX($O$4:$O$303,MATCH($W5,$T$4:$T$303,0)) -> Boulder Cottage | Y5: =INDEX($R$4:$R$303,MATCH($W5,$T$4:$T$303,0)) -> 62149.44 | Z5: =INDEX($O$4:$O$303,MATCH(301-$W5,$T$4:$T$303,0)) -> Timber Refuge | AA5: =INDEX($R$4:$R$303,MATCH(301-$W5,$T$4:$T$303,0)) -> 5402.758 | AB5: =INDEX($O$4:$O$303,MATCH($W5,$U$4:$U$303,0)) -> Bearpaw Villa | AC5: =INDEX($S$4:$S$303,MATCH($W5,$U$4:$U$303,0)) -> 5 | AD5: =INDEX($O$4:$O$303,MATCH(301-$W5,$U$4:$U$303,0)) -> Lakeview Retreat | AE5: =INDEX($S$4:$S$303,MATCH(301-$W5,$U$4:$U$303,0)) -> 2.7816667 | AG5: =R5+(ROW()-3)*0.0000001 -> 15717.295 | AH5: =S5+(ROW()-3)*0.0000001 -> 4.9183335 | AJ5: Supplies & Restocking | AK5: =IF(Dashboard!$C$3="All (Fiscal Year)",SUM(ExpensesTbl[Supplies & Restocking]),SUMIFS(ExpensesTbl[Supplies & Restocking],ExpensesTbl[Month],Dashboard!$C$3)) -> 34748.2
A6: =Revenue!A7 -> P0001 | B6: =Revenue!B7 -> Jun | C6: =A6&"|"&B6 -> P0001|Jun | D6: =Revenue!J7 -> 1007.2832 | E6: =_xlfn.XLOOKUP($C6,ExpensesTbl[Key],ExpensesTbl[Total Operating Expenses]) -> 548.78 | F6: =D6-E6 -> 458.5032 | G6: =_xlfn.XLOOKUP($A6,PropertiesTbl[Property ID],PropertiesTbl[Property Name]) -> Snowline Hideaway | I6: Jun | J6: =SUMIFS(CalcTbl[Total Revenue],CalcTbl[Month],$I6) -> 483101.64 | K6: =SUMIFS(CalcTbl[Total Expenses],CalcTbl[Month],$I6) -> 330236.58 | L6: =J6-K6 -> 152865.06 | N6: =Properties!A7 -> P0003 | O6: =_xlfn.XLOOKUP($N6,PropertiesTbl[Property ID],PropertiesTbl[Property Name]) -> Alpine Perch | P6: =SUMIFS(CalcTbl[Total Revenue],CalcTbl[Property ID],$N6,CalcTbl[Month],IF(Dashboard!$C$3="All (Fiscal Year)","*",Dashboard!$C$3)) -> 19882.165 | Q6: =SUMIFS(CalcTbl[Total Expenses],CalcTbl[Property ID],$N6,CalcTbl[Month],IF(Dashboard!$C$3="All (Fiscal Year)","*",Dashboard!$C$3)) -> 12314.21 | R6: =P6-Q6 -> 7567.9546 | S6: =_xlfn.XLOOKUP($N6,RatingsTbl[Property ID],RatingsTbl[Overall Rating]) -> 3.5583333 | T6: =_xlfn.RANK.EQ(AG6,$AG$4:$AG$303,0) -> 280 | U6: =_xlfn.RANK.EQ(AH6,$AH$4:$AH$303,0) -> 283 | W6: =ROW()-3 -> 3 | X6: =INDEX($O$4:$O$303,MATCH($W6,$T$4:$T$303,0)) -> Starlight Hollow | Y6: =INDEX($R$4:$R$303,MATCH($W6,$T$4:$T$303,0)) -> 61412.382 | Z6: =INDEX($O$4:$O$303,MATCH(301-$W6,$T$4:$T$303,0)) -> Cedar Perch | AA6: =INDEX($R$4:$R$303,MATCH(301-$W6,$T$4:$T$303,0)) -> 5705.8814 | AB6: =INDEX($O$4:$O$303,MATCH($W6,$U$4:$U$303,0)) -> Snowline Overlook | AC6: =INDEX($S$4:$S$303,MATCH($W6,$U$4:$U$303,0)) -> 5 | AD6: =INDEX($O$4:$O$303,MATCH(301-$W6,$U$4:$U$303,0)) -> Cinder Landing | AE6: =INDEX($S$4:$S$303,MATCH(301-$W6,$U$4:$U$303,0)) -> 2.835 | AG6: =R6+(ROW()-3)*0.0000001 -> 7567.9546 | AH6: =S6+(ROW()-3)*0.0000001 -> 3.5583336 | AJ6: Housekeeping Cost | AK6: =IF(Dashboard!$C$3="All (Fiscal Year)",SUM(ExpensesTbl[Housekeeping Cost]),SUMIFS(ExpensesTbl[Housekeeping Cost],ExpensesTbl[Month],Dashboard!$C$3)) -> 2018616.1
A7: =Revenue!A8 -> P0001 | B7: =Revenue!B8 -> Jul | C7: =A7&"|"&B7 -> P0001|Jul | D7: =Revenue!J8 -> 1503.4073 | E7: =_xlfn.XLOOKUP($C7,ExpensesTbl[Key],ExpensesTbl[Total Operating Expenses]) -> 902.87 | F7: =D7-E7 -> 600.5373 | G7: =_xlfn.XLOOKUP($A7,PropertiesTbl[Property ID],PropertiesTbl[Property Name]) -> Snowline Hideaway | I7: Jul | J7: =SUMIFS(CalcTbl[Total Revenue],CalcTbl[Month],$I7) -> 713584.26 | K7: =SUMIFS(CalcTbl[Total Expenses],CalcTbl[Month],$I7) -> 603783.64 | L7: =J7-K7 -> 109800.62 | N7: =Properties!A8 -> P0004 | O7: =_xlfn.XLOOKUP($N7,PropertiesTbl[Property ID],PropertiesTbl[Property Name]) -> Lakeview Villa | P7: =SUMIFS(CalcTbl[Total Revenue],CalcTbl[Property ID],$N7,CalcTbl[Month],IF(Dashboard!$C$3="All (Fiscal Year)","*",Dashboard!$C$3)) -> 33292.697 | Q7: =SUMIFS(CalcTbl[Total Expenses],CalcTbl[Property ID],$N7,CalcTbl[Month],IF(Dashboard!$C$3="All (Fiscal Year)","*",Dashboard!$C$3)) -> 16130.74 | R7: =P7-Q7 -> 17161.957 | S7: =_xlfn.XLOOKUP($N7,RatingsTbl[Property ID],RatingsTbl[Overall Rating]) -> 4.9566667 | T7: =_xlfn.RANK.EQ(AG7,$AG$4:$AG$303,0) -> 100 | U7: =_xlfn.RANK.EQ(AH7,$AH$4:$AH$303,0) -> 43 | W7: =ROW()-3 -> 4 | X7: =INDEX($O$4:$O$303,MATCH($W7,$T$4:$T$303,0)) -> Highland Escape | Y7: =INDEX($R$4:$R$303,MATCH($W7,$T$4:$T$303,0)) -> 56125.159 | Z7: =INDEX($O$4:$O$303,MATCH(301-$W7,$T$4:$T$303,0)) -> Pine Cottage | AA7: =INDEX($R$4:$R$303,MATCH(301-$W7,$T$4:$T$303,0)) -> 5924.0998 | AB7: =INDEX($O$4:$O$303,MATCH($W7,$U$4:$U$303,0)) -> Frost Manor | AC7: =INDEX($S$4:$S$303,MATCH($W7,$U$4:$U$303,0)) -> 4.985 | AD7: =INDEX($O$4:$O$303,MATCH(301-$W7,$U$4:$U$303,0)) -> Highland Escape | AE7: =INDEX($S$4:$S$303,MATCH(301-$W7,$U$4:$U$303,0)) -> 2.8516667 | AG7: =R7+(ROW()-3)*0.0000001 -> 17161.957 | AH7: =S7+(ROW()-3)*0.0000001 -> 4.9566671 | AJ7: Snow Removal & Winter Prep | AK7: =IF(Dashboard!$C$3="All (Fiscal Year)",SUM(ExpensesTbl[Snow Removal & Winter Prep]),SUMIFS(ExpensesTbl[Snow Removal & Winter Prep],ExpensesTbl[Month],Dashboard!$C$3)) -> 161285.12
A8: =Revenue!A9 -> P0001 | B8: =Revenue!B9 -> Aug | C8: =A8&"|"&B8 -> P0001|Aug | D8: =Revenue!J9 -> 1522.9334 | E8: =_xlfn.XLOOKUP($C8,ExpensesTbl[Key],ExpensesTbl[Total Operating Expenses]) -> 866.34 | F8: =D8-E8 -> 656.5934 | G8: =_xlfn.XLOOKUP($A8,PropertiesTbl[Property ID],PropertiesTbl[Property Name]) -> Snowline Hideaway | I8: Aug | J8: =SUMIFS(CalcTbl[Total Revenue],CalcTbl[Month],$I8) -> 666801.13 | K8: =SUMIFS(CalcTbl[Total Expenses],CalcTbl[Month],$I8) -> 567716.37 | L8: =J8-K8 -> 99084.76 | N8: =Properties!A9 -> P0005 | O8: =_xlfn.XLOOKUP($N8,PropertiesTbl[Property ID],PropertiesTbl[Property Name]) -> Evergreen Lodge | P8: =SUMIFS(CalcTbl[Total Revenue],CalcTbl[Property ID],$N8,CalcTbl[Month],IF(Dashboard!$C$3="All (Fiscal Year)","*",Dashboard!$C$3)) -> 49393.795 | Q8: =SUMIFS(CalcTbl[Total Expenses],CalcTbl[Property ID],$N8,CalcTbl[Month],IF(Dashboard!$C$3="All (Fiscal Year)","*",Dashboard!$C$3)) -> 23390.9 | R8: =P8-Q8 -> 26002.895 | S8: =_xlfn.XLOOKUP($N8,RatingsTbl[Property ID],RatingsTbl[Overall Rating]) -> 4.9366667 | T8: =_xlfn.RANK.EQ(AG8,$AG$4:$AG$303,0) -> 25 | U8: =_xlfn.RANK.EQ(AH8,$AH$4:$AH$303,0) -> 129 | W8: =ROW()-3 -> 5 | X8: =INDEX($O$4:$O$303,MATCH($W8,$T$4:$T$303,0)) -> Juniper Escape | Y8: =INDEX($R$4:$R$303,MATCH($W8,$T$4:$T$303,0)) -> 54531.892 | Z8: =INDEX($O$4:$O$303,MATCH(301-$W8,$T$4:$T$303,0)) -> Bearpaw Landing | AA8: =INDEX($R$4:$R$303,MATCH(301-$W8,$T$4:$T$303,0)) -> 6206.0879 | AB8: =INDEX($O$4:$O$303,MATCH($W8,$U$4:$U$303,0)) -> Alpine Haven | AC8: =INDEX($S$4:$S$303,MATCH($W8,$U$4:$U$303,0)) -> 4.9816667 | AD8: =INDEX($O$4:$O$303,MATCH(301-$W8,$U$4:$U$303,0)) -> Forest Nest | AE8: =INDEX($S$4:$S$303,MATCH(301-$W8,$U$4:$U$303,0)) -> 2.87 | AG8: =R8+(ROW()-3)*0.0000001 -> 26002.895 | AH8: =S8+(ROW()-3)*0.0000001 -> 4.9366672 | AJ8: Management & Software Overhead | AK8: =IF(Dashboard!$C$3="All (Fiscal Year)",SUM(ExpensesTbl[Management & Software Overhead]),SUMIFS(ExpensesTbl[Management & Software Overhead],ExpensesTbl[Month],Dashboard!$C$3)) -> 309456
A9: =Revenue!A10 -> P0001 | B9: =Revenue!B10 -> Sep | C9: =A9&"|"&B9 -> P0001|Sep | D9: =Revenue!J10 -> 870.9691 | E9: =_xlfn.XLOOKUP($C9,ExpensesTbl[Key],ExpensesTbl[Total Operating Expenses]) -> 470.99 | F9: =D9-E9 -> 399.9791 | G9: =_xlfn.XLOOKUP($A9,PropertiesTbl[Property ID],PropertiesTbl[Property Name]) -> Snowline Hideaway | I9: Sep | J9: =SUMIFS(CalcTbl[Total Revenue],CalcTbl[Month],$I9) -> 443225.46 | K9: =SUMIFS(CalcTbl[Total Expenses],CalcTbl[Month],$I9) -> 259289.37 | L9: =J9-K9 -> 183936.09 | N9: =Properties!A10 -> P0006 | O9: =_xlfn.XLOOKUP($N9,PropertiesTbl[Property ID],PropertiesTbl[Property Name]) -> Granite Landing | P9: =SUMIFS(CalcTbl[Total Revenue],CalcTbl[Property ID],$N9,CalcTbl[Month],IF(Dashboard!$C$3="All (Fiscal Year)","*",Dashboard!$C$3)) -> 25992.48 | Q9: =SUMIFS(CalcTbl[Total Expenses],CalcTbl[Property ID],$N9,CalcTbl[Month],IF(Dashboard!$C$3="All (Fiscal Year)","*",Dashboard!$C$3)) -> 12986.24 | R9: =P9-Q9 -> 13006.24 | S9: =_xlfn.XLOOKUP($N9,RatingsTbl[Property ID],RatingsTbl[Overall Rating]) -> 4.95 | T9: =_xlfn.RANK.EQ(AG9,$AG$4:$AG$303,0) -> 179 | U9: =_xlfn.RANK.EQ(AH9,$AH$4:$AH$303,0) -> 69 | W9: =ROW()-3 -> 6 | X9: =INDEX($O$4:$O$303,MATCH($W9,$T$4:$T$303,0)) -> Evergreen House | Y9: =INDEX($R$4:$R$303,MATCH($W9,$T$4:$T$303,0)) -> 45232.618 | Z9: =INDEX($O$4:$O$303,MATCH(301-$W9,$T$4:$T$303,0)) -> Sierra Hideaway | AA9: =INDEX($R$4:$R$303,MATCH(301-$W9,$T$4:$T$303,0)) -> 6282.3273 | AB9: =INDEX($O$4:$O$303,MATCH($W9,$U$4:$U$303,0)) -> Bearpaw Hideaway | AC9: =INDEX($S$4:$S$303,MATCH($W9,$U$4:$U$303,0)) -> 4.9783333 | AD9: =INDEX($O$4:$O$303,MATCH(301-$W9,$U$4:$U$303,0)) -> Timber Landing | AE9: =INDEX($S$4:$S$303,MATCH(301-$W9,$U$4:$U$303,0)) -> 2.9283333 | AG9: =R9+(ROW()-3)*0.0000001 -> 13006.24 | AH9: =S9+(ROW()-3)*0.0000001 -> 4.9500006 | AJ9: Seasonal Operations & Marketing | AK9: =IF(Dashboard!$C$3="All (Fiscal Year)",SUM(ExpensesTbl[Seasonal Operations & Marketing]),SUMIFS(ExpensesTbl[Seasonal Operations & Marketing],ExpensesTbl[Month],Dashboard!$C$3)) -> 1317122.3
A10: =Revenue!A11 -> P0001 | B10: =Revenue!B11 -> Oct | C10: =A10&"|"&B10 -> P0001|Oct | D10: =Revenue!J11 -> 805.5814 | E10: =_xlfn.XLOOKUP($C10,ExpensesTbl[Key],ExpensesTbl[Total Operating Expenses]) -> 731.67 | F10: =D10-E10 -> 73.9114 | G10: =_xlfn.XLOOKUP($A10,PropertiesTbl[Property ID],PropertiesTbl[Property Name]) -> Snowline Hideaway | I10: Oct | J10: =SUMIFS(CalcTbl[Total Revenue],CalcTbl[Month],$I10) -> 402944.6 | K10: =SUMIFS(CalcTbl[Total Expenses],CalcTbl[Month],$I10) -> 237358.45 | L10: =J10-K10 -> 165586.15 | N10: =Properties!A11 -> P0007 | O10: =_xlfn.XLOOKUP($N10,PropertiesTbl[Property ID],PropertiesTbl[Property Name]) -> Bearpaw Lodge | P10: =SUMIFS(CalcTbl[Total Revenue],CalcTbl[Property ID],$N10,CalcTbl[Month],IF(Dashboard!$C$3="All (Fiscal Year)","*",Dashboard!$C$3)) -> 27409.193 | Q10: =SUMIFS(CalcTbl[Total Expenses],CalcTbl[Property ID],$N10,CalcTbl[Month],IF(Dashboard!$C$3="All (Fiscal Year)","*",Dashboard!$C$3)) -> 13390.35 | R10: =P10-Q10 -> 14018.842 | S10: =_xlfn.XLOOKUP($N10,RatingsTbl[Property ID],RatingsTbl[Overall Rating]) -> 4.935 | T10: =_xlfn.RANK.EQ(AG10,$AG$4:$AG$303,0) -> 152 | U10: =_xlfn.RANK.EQ(AH10,$AH$4:$AH$303,0) -> 137 | W10: =ROW()-3 -> 7 | X10: =INDEX($O$4:$O$303,MATCH($W10,$T$4:$T$303,0)) -> Cloudline Chalet | Y10: =INDEX($R$4:$R$303,MATCH($W10,$T$4:$T$303,0)) -> 41426.595 | Z10: =INDEX($O$4:$O$303,MATCH(301-$W10,$T$4:$T$303,0)) -> Summit Cottage | AA10: =INDEX($R$4:$R$303,MATCH(301-$W10,$T$4:$T$303,0)) -> 6346.915 | AB10: =INDEX($O$4:$O$303,MATCH($W10,$U$4:$U$303,0)) -> Granite Refuge | AC10: =INDEX($S$4:$S$303,MATCH($W10,$U$4:$U$303,0)) -> 4.9733333 | AD10: =INDEX($O$4:$O$303,MATCH(301-$W10,$U$4:$U$303,0)) -> Bearpaw Point | AE10: =INDEX($S$4:$S$303,MATCH(301-$W10,$U$4:$U$303,0)) -> 2.965 | AG10: =R10+(ROW()-3)*0.0000001 -> 14018.843 | AH10: =S10+(ROW()-3)*0.0000001 -> 4.9350007
A11: =Revenue!A12 -> P0001 | B11: =Revenue!B12 -> Nov | C11: =A11&"|"&B11 -> P0001|Nov | D11: =Revenue!J12 -> 819.3748 | E11: =_xlfn.XLOOKUP($C11,ExpensesTbl[Key],ExpensesTbl[Total Operating Expenses]) -> 453.04 | F11: =D11-E11 -> 366.3348 | G11: =_xlfn.XLOOKUP($A11,PropertiesTbl[Property ID],PropertiesTbl[Property Name]) -> Snowline Hideaway | I11: Nov | J11: =SUMIFS(CalcTbl[Total Revenue],CalcTbl[Month],$I11) -> 425360.06 | K11: =SUMIFS(CalcTbl[Total Expenses],CalcTbl[Month],$I11) -> 224617.18 | L11: =J11-K11 -> 200742.88 | N11: =Properties!A12 -> P0008 | O11: =_xlfn.XLOOKUP($N11,PropertiesTbl[Property ID],PropertiesTbl[Property Name]) -> Alpine Overlook | P11: =SUMIFS(CalcTbl[Total Revenue],CalcTbl[Property ID],$N11,CalcTbl[Month],IF(Dashboard!$C$3="All (Fiscal Year)","*",Dashboard!$C$3)) -> 14236.625 | Q11: =SUMIFS(CalcTbl[Total Expenses],CalcTbl[Property ID],$N11,CalcTbl[Month],IF(Dashboard!$C$3="All (Fiscal Year)","*",Dashboard!$C$3)) -> 7605.3 | R11: =P11-Q11 -> 6631.3252 | S11: =_xlfn.XLOOKUP($N11,RatingsTbl[Property ID],RatingsTbl[Overall Rating]) -> 4.9316667 | T11: =_xlfn.RANK.EQ(AG11,$AG$4:$AG$303,0) -> 292 | U11: =_xlfn.RANK.EQ(AH11,$AH$4:$AH$303,0) -> 150 | W11: =ROW()-3 -> 8 | X11: =INDEX($O$4:$O$303,MATCH($W11,$T$4:$T$303,0)) -> Juniper Cottage | Y11: =INDEX($R$4:$R$303,MATCH($W11,$T$4:$T$303,0)) -> 34516.147 | Z11: =INDEX($O$4:$O$303,MATCH(301-$W11,$T$4:$T$303,0)) -> Highland Nest | AA11: =INDEX($R$4:$R$303,MATCH(301-$W11,$T$4:$T$303,0)) -> 6485.0543 | AB11: =INDEX($O$4:$O$303,MATCH($W11,$U$4:$U$303,0)) -> Copper Nest | AC11: =INDEX($S$4:$S$303,MATCH($W11,$U$4:$U$303,0)) -> 4.9716667 | AD11: =INDEX($O$4:$O$303,MATCH(301-$W11,$U$4:$U$303,0)) -> Juniper Perch | AE11: =INDEX($S$4:$S$303,MATCH(301-$W11,$U$4:$U$303,0)) -> 2.9916667 | AG11: =R11+(ROW()-3)*0.0000001 -> 6631.3252 | AH11: =S11+(ROW()-3)*0.0000001 -> 4.9316675
A12: =Revenue!A13 -> P0001 | B12: =Revenue!B13 -> Dec | C12: =A12&"|"&B12 -> P0001|Dec | D12: =Revenue!J13 -> 3282.702 | E12: =_xlfn.XLOOKUP($C12,ExpensesTbl[Key],ExpensesTbl[Total Operating Expenses]) -> 751.21 | F12: =D12-E12 -> 2531.492 | G12: =_xlfn.XLOOKUP($A12,PropertiesTbl[Property ID],PropertiesTbl[Property Name]) -> Snowline Hideaway | I12: Dec | J12: =SUMIFS(CalcTbl[Total Revenue],CalcTbl[Month],$I12) -> 1566001.7 | K12: =SUMIFS(CalcTbl[Total Expenses],CalcTbl[Month],$I12) -> 355427.41 | L12: =J12-K12 -> 1210574.3 | N12: =Properties!A13 -> P0009 | O12: =_xlfn.XLOOKUP($N12,PropertiesTbl[Property ID],PropertiesTbl[Property Name]) -> Ridge Cabin | P12: =SUMIFS(CalcTbl[Total Revenue],CalcTbl[Property ID],$N12,CalcTbl[Month],IF(Dashboard!$C$3="All (Fiscal Year)","*",Dashboard!$C$3)) -> 24648.711 | Q12: =SUMIFS(CalcTbl[Total Expenses],CalcTbl[Property ID],$N12,CalcTbl[Month],IF(Dashboard!$C$3="All (Fiscal Year)","*",Dashboard!$C$3)) -> 10463.88 | R12: =P12-Q12 -> 14184.831 | S12: =_xlfn.XLOOKUP($N12,RatingsTbl[Property ID],RatingsTbl[Overall Rating]) -> 4.935 | T12: =_xlfn.RANK.EQ(AG12,$AG$4:$AG$303,0) -> 148 | U12: =_xlfn.RANK.EQ(AH12,$AH$4:$AH$303,0) -> 136 | W12: =ROW()-3 -> 9 | X12: =INDEX($O$4:$O$303,MATCH($W12,$T$4:$T$303,0)) -> Birch Manor | Y12: =INDEX($R$4:$R$303,MATCH($W12,$T$4:$T$303,0)) -> 32408.18 | Z12: =INDEX($O$4:$O$303,MATCH(301-$W12,$T$4:$T$303,0)) -> Alpine Overlook | AA12: =INDEX($R$4:$R$303,MATCH(301-$W12,$T$4:$T$303,0)) -> 6631.3252 | AB12: =INDEX($O$4:$O$303,MATCH($W12,$U$4:$U$303,0)) -> Cloudline Landing | AC12: =INDEX($S$4:$S$303,MATCH($W12,$U$4:$U$303,0)) -> 4.9716667 | AD12: =INDEX($O$4:$O$303,MATCH(301-$W12,$U$4:$U$303,0)) -> Sierra Retreat | AE12: =INDEX($S$4:$S$303,MATCH(301-$W12,$U$4:$U$303,0)) -> 2.9983333 | AG12: =R12+(ROW()-3)*0.0000001 -> 14184.831 | AH12: =S12+(ROW()-3)*0.0000001 -> 4.9350009
A13: =Revenue!A14 -> P0001 | B13: =Revenue!B14 -> Jan | C13: =A13&"|"&B13 -> P0001|Jan | D13: =Revenue!J14 -> 2745.576 | E13: =_xlfn.XLOOKUP($C13,ExpensesTbl[Key],ExpensesTbl[Total Operating Expenses]) -> 694.58 | F13: =D13-E13 -> 2050.996 | G13: =_xlfn.XLOOKUP($A13,PropertiesTbl[Property ID],PropertiesTbl[Property Name]) -> Snowline Hideaway | I13: Jan | J13: =SUMIFS(CalcTbl[Total Revenue],CalcTbl[Month],$I13) -> 1348860.5 | K13: =SUMIFS(CalcTbl[Total Expenses],CalcTbl[Month],$I13) -> 340451.1 | L13: =J13-K13 -> 1008409.4 | N13: =Properties!A14 -> P0010 | O13: =_xlfn.XLOOKUP($N13,PropertiesTbl[Property ID],PropertiesTbl[Property Name]) -> Aspen Cabin | P13: =SUMIFS(CalcTbl[Total Revenue],CalcTbl[Property ID],$N13,CalcTbl[Month],IF(Dashboard!$C$3="All (Fiscal Year)","*",Dashboard!$C$3)) -> 26906.781 | Q13: =SUMIFS(CalcTbl[Total Expenses],CalcTbl[Property ID],$N13,CalcTbl[Month],IF(Dashboard!$C$3="All (Fiscal Year)","*",Dashboard!$C$3)) -> 13331.48 | R13: =P13-Q13 -> 13575.301 | S13: =_xlfn.XLOOKUP($N13,RatingsTbl[Property ID],RatingsTbl[Overall Rating]) -> 4.9333333 | T13: =_xlfn.RANK.EQ(AG13,$AG$4:$AG$303,0) -> 165 | U13: =_xlfn.RANK.EQ(AH13,$AH$4:$AH$303,0) -> 143 | W13: =ROW()-3 -> 10 | X13: =INDEX($O$4:$O$303,MATCH($W13,$T$4:$T$303,0)) -> Mountain Getaway | Y13: =INDEX($R$4:$R$303,MATCH($W13,$T$4:$T$303,0)) -> 32291.495 | Z13: =INDEX($O$4:$O$303,MATCH(301-$W13,$T$4:$T$303,0)) -> Golden Refuge | AA13: =INDEX($R$4:$R$303,MATCH(301-$W13,$T$4:$T$303,0)) -> 6754.0566 | AB13: =INDEX($O$4:$O$303,MATCH($W13,$U$4:$U$303,0)) -> Timber Hollow | AC13: =INDEX($S$4:$S$303,MATCH($W13,$U$4:$U$303,0)) -> 4.9716667 | AD13: =INDEX($O$4:$O$303,MATCH(301-$W13,$U$4:$U$303,0)) -> Aspen Landing | AE13: =INDEX($S$4:$S$303,MATCH(301-$W13,$U$4:$U$303,0)) -> 3.25 | AG13: =R13+(ROW()-3)*0.0000001 -> 13575.301 | AH13: =S13+(ROW()-3)*0.0000001 -> 4.9333343
A14: =Revenue!A15 -> P0001 | B14: =Revenue!B15 -> Feb | C14: =A14&"|"&B14 -> P0001|Feb | D14: =Revenue!J15 -> 2286.8824 | E14: =_xlfn.XLOOKUP($C14,ExpensesTbl[Key],ExpensesTbl[Total Operating Expenses]) -> 695.29 | F14: =D14-E14 -> 1591.5924 | G14: =_xlfn.XLOOKUP($A14,PropertiesTbl[Property ID],PropertiesTbl[Property Name]) -> Snowline Hideaway | I14: Feb | J14: =SUMIFS(CalcTbl[Total Revenue],CalcTbl[Month],$I14) -> 1095138.5 | K14: =SUMIFS(CalcTbl[Total Expenses],CalcTbl[Month],$I14) -> 313564.63 | L14: =J14-K14 -> 781573.91 | N14: =Properties!A15 -> P0011 | O14: =_xlfn.XLOOKUP($N14,PropertiesTbl[Property ID],PropertiesTbl[Property Name]) -> Frost Overlook | P14: =SUMIFS(CalcTbl[Total Revenue],CalcTbl[Property ID],$N14,CalcTbl[Month],IF(Dashboard!$C$3="All (Fiscal Year)","*",Dashboard!$C$3)) -> 44030.802 | Q14: =SUMIFS(CalcTbl[Total Expenses],CalcTbl[Property ID],$N14,CalcTbl[Month],IF(Dashboard!$C$3="All (Fiscal Year)","*",Dashboard!$C$3)) -> 17029.37 | R14: =P14-Q14 -> 27001.432 | S14: =_xlfn.XLOOKUP($N14,RatingsTbl[Property ID],RatingsTbl[Overall Rating]) -> 4.9683333 | T14: =_xlfn.RANK.EQ(AG14,$AG$4:$AG$303,0) -> 21 | U14: =_xlfn.RANK.EQ(AH14,$AH$4:$AH$303,0) -> 17 | AG14: =R14+(ROW()-3)*0.0000001 -> 27001.432 | AH14: =S14+(ROW()-3)*0.0000001 -> 4.9683344
A15: =Revenue!A16 -> P0001 | B15: =Revenue!B16 -> Mar | C15: =A15&"|"&B15 -> P0001|Mar | D15: =Revenue!J16 -> 1919.39 | E15: =_xlfn.XLOOKUP($C15,ExpensesTbl[Key],ExpensesTbl[Total Operating Expenses]) -> 607.44 | F15: =D15-E15 -> 1311.95 | G15: =_xlfn.XLOOKUP($A15,PropertiesTbl[Property ID],PropertiesTbl[Property Name]) -> Snowline Hideaway | I15: Mar | J15: =SUMIFS(CalcTbl[Total Revenue],CalcTbl[Month],$I15) -> 930448.53 | K15: =SUMIFS(CalcTbl[Total Expenses],CalcTbl[Month],$I15) -> 291533.35 | L15: =J15-K15 -> 638915.18 | N15: =Properties!A16 -> P0012 | O15: =_xlfn.XLOOKUP($N15,PropertiesTbl[Property ID],PropertiesTbl[Property Name]) -> Cedar Den | P15: =SUMIFS(CalcTbl[Total Revenue],CalcTbl[Property ID],$N15,CalcTbl[Month],IF(Dashboard!$C$3="All (Fiscal Year)","*",Dashboard!$C$3)) -> 30472.912 | Q15: =SUMIFS(CalcTbl[Total Expenses],CalcTbl[Property ID],$N15,CalcTbl[Month],IF(Dashboard!$C$3="All (Fiscal Year)","*",Dashboard!$C$3)) -> 15681.3 | R15: =P15-Q15 -> 14791.612 | S15: =_xlfn.XLOOKUP($N15,RatingsTbl[Property ID],RatingsTbl[Overall Rating]) -> 4.9216667 | T15: =_xlfn.RANK.EQ(AG15,$AG$4:$AG$303,0) -> 134 | U15: =_xlfn.RANK.EQ(AH15,$AH$4:$AH$303,0) -> 195 | AG15: =R15+(ROW()-3)*0.0000001 -> 14791.612 | AH15: =S15+(ROW()-3)*0.0000001 -> 4.9216679
A16: =Revenue!A17 -> P0002 | B16: =Revenue!B17 -> Apr | C16: =A16&"|"&B16 -> P0002|Apr | D16: =Revenue!J17 -> 1254.6885 | E16: =_xlfn.XLOOKUP($C16,ExpensesTbl[Key],ExpensesTbl[Total Operating Expenses]) -> 800.93 | F16: =D16-E16 -> 453.7585 | G16: =_xlfn.XLOOKUP($A16,PropertiesTbl[Property ID],PropertiesTbl[Property Name]) -> Meadow Lodge | N16: =Properties!A17 -> P0013 | O16: =_xlfn.XLOOKUP($N16,PropertiesTbl[Property ID],PropertiesTbl[Property Name]) -> Lakeview Nest | P16: =SUMIFS(CalcTbl[Total Revenue],CalcTbl[Property ID],$N16,CalcTbl[Month],IF(Dashboard!$C$3="All (Fiscal Year)","*",Dashboard!$C$3)) -> 25590.988 | Q16: =SUMIFS(CalcTbl[Total Expenses],CalcTbl[Property ID],$N16,CalcTbl[Month],IF(Dashboard!$C$3="All (Fiscal Year)","*",Dashboard!$C$3)) -> 12793.42 | R16: =P16-Q16 -> 12797.568 | S16: =_xlfn.XLOOKUP($N16,RatingsTbl[Property ID],RatingsTbl[Overall Rating]) -> 4.9233333 | T16: =_xlfn.RANK.EQ(AG16,$AG$4:$AG$303,0) -> 187 | U16: =_xlfn.RANK.EQ(AH16,$AH$4:$AH$303,0) -> 187 | AG16: =R16+(ROW()-3)*0.0000001 -> 12797.568 | AH16: =S16+(ROW()-3)*0.0000001 -> 4.9233346
A17: =Revenue!A18 -> P0002 | B17: =Revenue!B18 -> May | C17: =A17&"|"&B17 -> P0002|May | D17: =Revenue!J18 -> 1609.5436 | E17: =_xlfn.XLOOKUP($C17,ExpensesTbl[Key],ExpensesTbl[Total Operating Expenses]) -> 1179.95 | F17: =D17-E17 -> 429.5936 | G17: =_xlfn.XLOOKUP($A17,PropertiesTbl[Property ID],PropertiesTbl[Property Name]) -> Meadow Lodge | N17: =Properties!A18 -> P0014 | O17: =_xlfn.XLOOKUP($N17,PropertiesTbl[Property ID],PropertiesTbl[Property Name]) -> Whispering Den | P17: =SUMIFS(CalcTbl[Total Revenue],CalcTbl[Property ID],$N17,CalcTbl[Month],IF(Dashboard!$C$3="All (Fiscal Year)","*",Dashboard!$C$3)) -> 17056.834 | Q17: =SUMIFS(CalcTbl[Total Expenses],CalcTbl[Property ID],$N17,CalcTbl[Month],IF(Dashboard!$C$3="All (Fiscal Year)","*",Dashboard!$C$3)) -> 7292.89 | R17: =P17-Q17 -> 9763.9441 | S17: =_xlfn.XLOOKUP($N17,RatingsTbl[Property ID],RatingsTbl[Overall Rating]) -> 4.9266667 | T17: =_xlfn.RANK.EQ(AG17,$AG$4:$AG$303,0) -> 245 | U17: =_xlfn.RANK.EQ(AH17,$AH$4:$AH$303,0) -> 176 | AG17: =R17+(ROW()-3)*0.0000001 -> 9763.9441 | AH17: =S17+(ROW()-3)*0.0000001 -> 4.9266681
A18: =Revenue!A19 -> P0002 | B18: =Revenue!B19 -> Jun | C18: =A18&"|"&B18 -> P0002|Jun | D18: =Revenue!J19 -> 1542.9046 | E18: =_xlfn.XLOOKUP($C18,ExpensesTbl[Key],ExpensesTbl[Total Operating Expenses]) -> 1380.04 | F18: =D18-E18 -> 162.8646 | G18: =_xlfn.XLOOKUP($A18,PropertiesTbl[Property ID],PropertiesTbl[Property Name]) -> Meadow Lodge | N18: =Properties!A19 -> P0015 | O18: =_xlfn.XLOOKUP($N18,PropertiesTbl[Property ID],PropertiesTbl[Property Name]) -> Evergreen Refuge | P18: =SUMIFS(CalcTbl[Total Revenue],CalcTbl[Property ID],$N18,CalcTbl[Month],IF(Dashboard!$C$3="All (Fiscal Year)","*",Dashboard!$C$3)) -> 22399.461 | Q18: =SUMIFS(CalcTbl[Total Expenses],CalcTbl[Property ID],$N18,CalcTbl[Month],IF(Dashboard!$C$3="All (Fiscal Year)","*",Dashboard!$C$3)) -> 10299.59 | R18: =P18-Q18 -> 12099.871 | S18: =_xlfn.XLOOKUP($N18,RatingsTbl[Property ID],RatingsTbl[Overall Rating]) -> 4.9016667 | T18: =_xlfn.RANK.EQ(AG18,$AG$4:$AG$303,0) -> 205 | U18: =_xlfn.RANK.EQ(AH18,$AH$4:$AH$303,0) -> 256 | AG18: =R18+(ROW()-3)*0.0000001 -> 12099.871 | AH18: =S18+(ROW()-3)*0.0000001 -> 4.9016682
A19: =Revenue!A20 -> P0002 | B19: =Revenue!B20 -> Jul | C19: =A19&"|"&B19 -> P0002|Jul | D19: =Revenue!J20 -> 3083.014 | E19: =_xlfn.XLOOKUP($C19,ExpensesTbl[Key],ExpensesTbl[Total Operating Expenses]) -> 2607.42 | F19: =D19-E19 -> 475.594 | G19: =_xlfn.XLOOKUP($A19,PropertiesTbl[Property ID],PropertiesTbl[Property Name]) -> Meadow Lodge | N19: =Properties!A20 -> P0016 | O19: =_xlfn.XLOOKUP($N19,PropertiesTbl[Property ID],PropertiesTbl[Property Name]) -> Cedar Nest | P19: =SUMIFS(CalcTbl[Total Revenue],CalcTbl[Property ID],$N19,CalcTbl[Month],IF(Dashboard!$C$3="All (Fiscal Year)","*",Dashboard!$C$3)) -> 40431.879 | Q19: =SUMIFS(CalcTbl[Total Expenses],CalcTbl[Property ID],$N19,CalcTbl[Month],IF(Dashboard!$C$3="All (Fiscal Year)","*",Dashboard!$C$3)) -> 19154.23 | R19: =P19-Q19 -> 21277.649 | S19: =_xlfn.XLOOKUP($N19,RatingsTbl[Property ID],RatingsTbl[Overall Rating]) -> 4.95 | T19: =_xlfn.RANK.EQ(AG19,$AG$4:$AG$303,0) -> 57 | U19: =_xlfn.RANK.EQ(AH19,$AH$4:$AH$303,0) -> 68 | AG19: =R19+(ROW()-3)*0.0000001 -> 21277.649 | AH19: =S19+(ROW()-3)*0.0000001 -> 4.9500016
A20: =Revenue!A21 -> P0002 | B20: =Revenue!B21 -> Aug | C20: =A20&"|"&B20 -> P0002|Aug | D20: =Revenue!J21 -> 2261.8104 | E20: =_xlfn.XLOOKUP($C20,ExpensesTbl[Key],ExpensesTbl[Total Operating Expenses]) -> 2330.54 | F20: =D20-E20 -> -68.7296 | G20: =_xlfn.XLOOKUP($A20,PropertiesTbl[Property ID],PropertiesTbl[Property Name]) -> Meadow Lodge | N20: =Properties!A21 -> P0017 | O20: =_xlfn.XLOOKUP($N20,PropertiesTbl[Property ID],PropertiesTbl[Property Name]) -> Cedar Perch | P20: =SUMIFS(CalcTbl[Total Revenue],CalcTbl[Property ID],$N20,CalcTbl[Month],IF(Dashboard!$C$3="All (Fiscal Year)","*",Dashboard!$C$3)) -> 15074.041 | Q20: =SUMIFS(CalcTbl[Total Expenses],CalcTbl[Property ID],$N20,CalcTbl[Month],IF(Dashboard!$C$3="All (Fiscal Year)","*",Dashboard!$C$3)) -> 9368.16 | R20: =P20-Q20 -> 5705.8814 | S20: =_xlfn.XLOOKUP($N20,RatingsTbl[Property ID],RatingsTbl[Overall Rating]) -> 3.3183333 | T20: =_xlfn.RANK.EQ(AG20,$AG$4:$AG$303,0) -> 298 | U20: =_xlfn.RANK.EQ(AH20,$AH$4:$AH$303,0) -> 288 | AG20: =R20+(ROW()-3)*0.0000001 -> 5705.8814 | AH20: =S20+(ROW()-3)*0.0000001 -> 3.318335
A21: =Revenue!A22 -> P0002 | B21: =Revenue!B22 -> Sep | C21: =A21&"|"&B21 -> P0002|Sep | D21: =Revenue!J22 -> 1535.455 | E21: =_xlfn.XLOOKUP($C21,ExpensesTbl[Key],ExpensesTbl[Total Operating Expenses]) -> 1037.94 | F21: =D21-E21 -> 497.515 | G21: =_xlfn.XLOOKUP($A21,PropertiesTbl[Property ID],PropertiesTbl[Property Name]) -> Meadow Lodge | N21: =Properties!A22 -> P0018 | O21: =_xlfn.XLOOKUP($N21,PropertiesTbl[Property ID],PropertiesTbl[Property Name]) -> Juniper Hideaway | P21: =SUMIFS(CalcTbl[Total Revenue],CalcTbl[Property ID],$N21,CalcTbl[Month],IF(Dashboard!$C$3="All (Fiscal Year)","*",Dashboard!$C$3)) -> 23614.022 | Q21: =SUMIFS(CalcTbl[Total Expenses],CalcTbl[Property ID],$N21,CalcTbl[Month],IF(Dashboard!$C$3="All (Fiscal Year)","*",Dashboard!$C$3)) -> 13274.08 | R21: =P21-Q21 -> 10339.942 | S21: =_xlfn.XLOOKUP($N21,RatingsTbl[Property ID],RatingsTbl[Overall Rating]) -> 4.9033333 | T21: =_xlfn.RANK.EQ(AG21,$AG$4:$AG$303,0) -> 233 | U21: =_xlfn.RANK.EQ(AH21,$AH$4:$AH$303,0) -> 250 | AG21: =R21+(ROW()-3)*0.0000001 -> 10339.942 | AH21: =S21+(ROW()-3)*0.0000001 -> 4.9033351
A22: =Revenue!A23 -> P0002 | B22: =Revenue!B23 -> Oct | C22: =A22&"|"&B22 -> P0002|Oct | D22: =Revenue!J23 -> 1565.8354 | E22: =_xlfn.XLOOKUP($C22,ExpensesTbl[Key],ExpensesTbl[Total Operating Expenses]) -> 935.77 | F22: =D22-E22 -> 630.0654 | G22: =_xlfn.XLOOKUP($A22,PropertiesTbl[Property ID],PropertiesTbl[Property Name]) -> Meadow Lodge | N22: =Properties!A23 -> P0019 | O22: =_xlfn.XLOOKUP($N22,PropertiesTbl[Property ID],PropertiesTbl[Property Name]) -> Mountain Overlook | P22: =SUMIFS(CalcTbl[Total Revenue],CalcTbl[Property ID],$N22,CalcTbl[Month],IF(Dashboard!$C$3="All (Fiscal Year)","*",Dashboard!$C$3)) -> 44389.929 | Q22: =SUMIFS(CalcTbl[Total Expenses],CalcTbl[Property ID],$N22,CalcTbl[Month],IF(Dashboard!$C$3="All (Fiscal Year)","*",Dashboard!$C$3)) -> 19973.03 | R22: =P22-Q22 -> 24416.899 | S22: =_xlfn.XLOOKUP($N22,RatingsTbl[Property ID],RatingsTbl[Overall Rating]) -> 4.9133333 | T22: =_xlfn.RANK.EQ(AG22,$AG$4:$AG$303,0) -> 32 | U22: =_xlfn.RANK.EQ(AH22,$AH$4:$AH$303,0) -> 223 | AG22: =R22+(ROW()-3)*0.0000001 -> 24416.899 | AH22: =S22+(ROW()-3)*0.0000001 -> 4.9133352
A23: =Revenue!A24 -> P0002 | B23: =Revenue!B24 -> Nov | C23: =A23&"|"&B23 -> P0002|Nov | D23: =Revenue!J24 -> 1645.0456 | E23: =_xlfn.XLOOKUP($C23,ExpensesTbl[Key],ExpensesTbl[Total Operating Expenses]) -> 845.06 | F23: =D23-E23 -> 799.9856 | G23: =_xlfn.XLOOKUP($A23,PropertiesTbl[Property ID],PropertiesTbl[Property Name]) -> Meadow Lodge | N23: =Properties!A24 -> P0020 | O23: =_xlfn.XLOOKUP($N23,PropertiesTbl[Property ID],PropertiesTbl[Property Name]) -> Timber Perch | P23: =SUMIFS(CalcTbl[Total Revenue],CalcTbl[Property ID],$N23,CalcTbl[Month],IF(Dashboard!$C$3="All (Fiscal Year)","*",Dashboard!$C$3)) -> 16903.662 | Q23: =SUMIFS(CalcTbl[Total Expenses],CalcTbl[Property ID],$N23,CalcTbl[Month],IF(Dashboard!$C$3="All (Fiscal Year)","*",Dashboard!$C$3)) -> 7529.52 | R23: =P23-Q23 -> 9374.1421 | S23: =_xlfn.XLOOKUP($N23,RatingsTbl[Property ID],RatingsTbl[Overall Rating]) -> 4.9683333 | T23: =_xlfn.RANK.EQ(AG23,$AG$4:$AG$303,0) -> 253 | U23: =_xlfn.RANK.EQ(AH23,$AH$4:$AH$303,0) -> 16 | AG23: =R23+(ROW()-3)*0.0000001 -> 9374.1421 | AH23: =S23+(ROW()-3)*0.0000001 -> 4.9683353
A24: =Revenue!A25 -> P0002 | B24: =Revenue!B25 -> Dec | C24: =A24&"|"&B24 -> P0002|Dec | D24: =Revenue!J25 -> 5530.6764 | E24: =_xlfn.XLOOKUP($C24,ExpensesTbl[Key],ExpensesTbl[Total Operating Expenses]) -> 1317.47 | F24: =D24-E24 -> 4213.2064 | G24: =_xlfn.XLOOKUP($A24,PropertiesTbl[Property ID],PropertiesTbl[Property Name]) -> Meadow Lodge | N24: =Properties!A25 -> P0021 | O24: =_xlfn.XLOOKUP($N24,PropertiesTbl[Property ID],PropertiesTbl[Property Name]) -> Lakeview Den | P24: =SUMIFS(CalcTbl[Total Revenue],CalcTbl[Property ID],$N24,CalcTbl[Month],IF(Dashboard!$C$3="All (Fiscal Year)","*",Dashboard!$C$3)) -> 29103.489 | Q24: =SUMIFS(CalcTbl[Total Expenses],CalcTbl[Property ID],$N24,CalcTbl[Month],IF(Dashboard!$C$3="All (Fiscal Year)","*",Dashboard!$C$3)) -> 13497.18 | R24: =P24-Q24 -> 15606.309 | S24: =_xlfn.XLOOKUP($N24,RatingsTbl[Property ID],RatingsTbl[Overall Rating]) -> 4.9083333 | T24: =_xlfn.RANK.EQ(AG24,$AG$4:$AG$303,0) -> 120 | U24: =_xlfn.RANK.EQ(AH24,$AH$4:$AH$303,0) -> 238 | AG24: =R24+(ROW()-3)*0.0000001 -> 15606.309 | AH24: =S24+(ROW()-3)*0.0000001 -> 4.9083354
A25: =Revenue!A26 -> P0002 | B25: =Revenue!B26 -> Jan | C25: =A25&"|"&B25 -> P0002|Jan | D25: =Revenue!J26 -> 4290.4425 | E25: =_xlfn.XLOOKUP($C25,ExpensesTbl[Key],ExpensesTbl[Total Operating Expenses]) -> 1190.58 | F25: =D25-E25 -> 3099.8625 | G25: =_xlfn.XLOOKUP($A25,PropertiesTbl[Property ID],PropertiesTbl[Property Name]) -> Meadow Lodge | N25: =Properties!A26 -> P0022 | O25: =_xlfn.XLOOKUP($N25,PropertiesTbl[Property ID],PropertiesTbl[Property Name]) -> Mountain Perch | P25: =SUMIFS(CalcTbl[Total Revenue],CalcTbl[Property ID],$N25,CalcTbl[Month],IF(Dashboard!$C$3="All (Fiscal Year)","*",Dashboard!$C$3)) -> 53433.467 | Q25: =SUMIFS(CalcTbl[Total Expenses],CalcTbl[Property ID],$N25,CalcTbl[Month],IF(Dashboard!$C$3="All (Fiscal Year)","*",Dashboard!$C$3)) -> 23438.9 | R25: =P25-Q25 -> 29994.567 | S25: =_xlfn.XLOOKUP($N25,RatingsTbl[Property ID],RatingsTbl[Overall Rating]) -> 4.9216667 | T25: =_xlfn.RANK.EQ(AG25,$AG$4:$AG$303,0) -> 13 | U25: =_xlfn.RANK.EQ(AH25,$AH$4:$AH$303,0) -> 194 | AG25: =R25+(ROW()-3)*0.0000001 -> 29994.567 | AH25: =S25+(ROW()-3)*0.0000001 -> 4.9216689
A26: =Revenue!A27 -> P0002 | B26: =Revenue!B27 -> Feb | C26: =A26&"|"&B26 -> P0002|Feb | D26: =Revenue!J27 -> 3986.3475 | E26: =_xlfn.XLOOKUP($C26,ExpensesTbl[Key],ExpensesTbl[Total Operating Expenses]) -> 1196.58 | F26: =D26-E26 -> 2789.7675 | G26: =_xlfn.XLOOKUP($A26,PropertiesTbl[Property ID],PropertiesTbl[Property Name]) -> Meadow Lodge | N26: =Properties!A27 -> P0023 | O26: =_xlfn.XLOOKUP($N26,PropertiesTbl[Property ID],PropertiesTbl[Property Name]) -> Cinder Haven | P26: =SUMIFS(CalcTbl[Total Revenue],CalcTbl[Property ID],$N26,CalcTbl[Month],IF(Dashboard!$C$3="All (Fiscal Year)","*",Dashboard!$C$3)) -> 23326.217 | Q26: =SUMIFS(CalcTbl[Total Expenses],CalcTbl[Property ID],$N26,CalcTbl[Month],IF(Dashboard!$C$3="All (Fiscal Year)","*",Dashboard!$C$3)) -> 10511.81 | R26: =P26-Q26 -> 12814.407 | S26: =_xlfn.XLOOKUP($N26,RatingsTbl[Property ID],RatingsTbl[Overall Rating]) -> 4.955 | T26: =_xlfn.RANK.EQ(AG26,$AG$4:$AG$303,0) -> 186 | U26: =_xlfn.RANK.EQ(AH26,$AH$4:$AH$303,0) -> 49 | AG26: =R26+(ROW()-3)*0.0000001 -> 12814.407 | AH26: =S26+(ROW()-3)*0.0000001 -> 4.9550023
A27: =Revenue!A28 -> P0002 | B27: =Revenue!B28 -> Mar | C27: =A27&"|"&B27 -> P0002|Mar | D27: =Revenue!J28 -> 3415.551 | E27: =_xlfn.XLOOKUP($C27,ExpensesTbl[Key],ExpensesTbl[Total Operating Expenses]) -> 1181.74 | F27: =D27-E27 -> 2233.811 | G27: =_xlfn.XLOOKUP($A27,PropertiesTbl[Property ID],PropertiesTbl[Property Name]) -> Meadow Lodge | N27: =Properties!A28 -> P0024 | O27: =_xlfn.XLOOKUP($N27,PropertiesTbl[Property ID],PropertiesTbl[Property Name]) -> Evergreen Escape | P27: =SUMIFS(CalcTbl[Total Revenue],CalcTbl[Property ID],$N27,CalcTbl[Month],IF(Dashboard!$C$3="All (Fiscal Year)","*",Dashboard!$C$3)) -> 25758.701 | Q27: =SUMIFS(CalcTbl[Total Expenses],CalcTbl[Property ID],$N27,CalcTbl[Month],IF(Dashboard!$C$3="All (Fiscal Year)","*",Dashboard!$C$3)) -> 12936.8 | R27: =P27-Q27 -> 12821.901 | S27: =_xlfn.XLOOKUP($N27,RatingsTbl[Property ID],RatingsTbl[Overall Rating]) -> 4.9016667 | T27: =_xlfn.RANK.EQ(AG27,$AG$4:$AG$303,0) -> 185 | U27: =_xlfn.RANK.EQ(AH27,$AH$4:$AH$303,0) -> 255 | AG27: =R27+(ROW()-3)*0.0000001 -> 12821.901 | AH27: =S27+(ROW()-3)*0.0000001 -> 4.9016691
... A303: =Revenue!A304 -> P0025 | B303: =Revenue!B304 -> Mar | C303: =A303&"|"&B303 -> P0025|Mar | D303: =Revenue!J304 -> 3680.5644 | E303: =_xlfn.XLOOKUP($C303,ExpensesTbl[Key],ExpensesTbl[Total Operating Expenses]) -> 1217.61 | F303: =D303-E303 -> 2462.9544 | G303: =_xlfn.XLOOKUP($A303,PropertiesTbl[Property ID],PropertiesTbl[Property Name]) -> Forest Chalet | N303: =Properties!A304 -> P0300 | O303: =_xlfn.XLOOKUP($N303,PropertiesTbl[Property ID],PropertiesTbl[Property Name]) -> Trailside Cottage | P303: =SUMIFS(CalcTbl[Total Revenue],CalcTbl[Property ID],$N303,CalcTbl[Month],IF(Dashboard!$C$3="All (Fiscal Year)","*",Dashboard!$C$3)) -> 38815.236 | Q303: =SUMIFS(CalcTbl[Total Expenses],CalcTbl[Property ID],$N303,CalcTbl[Month],IF(Dashboard!$C$3="All (Fiscal Year)","*",Dashboard!$C$3)) -> 16890.45 | R303: =P303-Q303 -> 21924.786 | S303: =_xlfn.XLOOKUP($N303,RatingsTbl[Property ID],RatingsTbl[Overall Rating]) -> 4.9533333 | T303: =_xlfn.RANK.EQ(AG303,$AG$4:$AG$303,0) -> 51 | U303: =_xlfn.RANK.EQ(AH303,$AH$4:$AH$303,0) -> 50 | AG303: =R303+(ROW()-3)*0.0000001 -> 21924.786 | AH303: =S303+(ROW()-3)*0.0000001 -> 4.9533633
A304: =Revenue!A305 -> P0026 | B304: =Revenue!B305 -> Apr | C304: =A304&"|"&B304 -> P0026|Apr | D304: =Revenue!J305 -> 781.5995 | E304: =_xlfn.XLOOKUP($C304,ExpensesTbl[Key],ExpensesTbl[Total Operating Expenses]) -> 519.28 | F304: =D304-E304 -> 262.3195 | G304: =_xlfn.XLOOKUP($A304,PropertiesTbl[Property ID],PropertiesTbl[Property Name]) -> Frost Cabin
A305: =Revenue!A306 -> P0026 | B305: =Revenue!B306 -> May | C305: =A305&"|"&B305 -> P0026|May | D305: =Revenue!J306 -> 997.4245 | E305: =_xlfn.XLOOKUP($C305,ExpensesTbl[Key],ExpensesTbl[Total Operating Expenses]) -> 722.89 | F305: =D305-E305 -> 274.5345 | G305: =_xlfn.XLOOKUP($A305,PropertiesTbl[Property ID],PropertiesTbl[Property Name]) -> Frost Cabin
A306: =Revenue!A307 -> P0026 | B306: =Revenue!B307 -> Jun | C306: =A306&"|"&B306 -> P0026|Jun | D306: =Revenue!J307 -> 965.9868 | E306: =_xlfn.XLOOKUP($C306,ExpensesTbl[Key],ExpensesTbl[Total Operating Expenses]) -> 806.22 | F306: =D306-E306 -> 159.7668 | G306: =_xlfn.XLOOKUP($A306,PropertiesTbl[Property ID],PropertiesTbl[Property Name]) -> Frost Cabin
A307: =Revenue!A308 -> P0026 | B307: =Revenue!B308 -> Jul | C307: =A307&"|"&B307 -> P0026|Jul | D307: =Revenue!J308 -> 1300.9472 | E307: =_xlfn.XLOOKUP($C307,ExpensesTbl[Key],ExpensesTbl[Total Operating Expenses]) -> 1370.43 | F307: =D307-E307 -> -69.4828 | G307: =_xlfn.XLOOKUP($A307,PropertiesTbl[Property ID],PropertiesTbl[Property Name]) -> Frost Cabin
A308: =Revenue!A309 -> P0026 | B308: =Revenue!B309 -> Aug | C308: =A308&"|"&B308 -> P0026|Aug | D308: =Revenue!J309 -> 1614.695 | E308: =_xlfn.XLOOKUP($C308,ExpensesTbl[Key],ExpensesTbl[Total Operating Expenses]) -> 1375.79 | F308: =D308-E308 -> 238.905 | G308: =_xlfn.XLOOKUP($A308,PropertiesTbl[Property ID],PropertiesTbl[Property Name]) -> Frost Cabin
A309: =Revenue!A310 -> P0026 | B309: =Revenue!B310 -> Sep | C309: =A309&"|"&B309 -> P0026|Sep | D309: =Revenue!J310 -> 887.6496 | E309: =_xlfn.XLOOKUP($C309,ExpensesTbl[Key],ExpensesTbl[Total Operating Expenses]) -> 657.1 | F309: =D309-E309 -> 230.5496 | G309: =_xlfn.XLOOKUP($A309,PropertiesTbl[Property ID],PropertiesTbl[Property Name]) -> Frost Cabin
A310: =Revenue!A311 -> P0026 | B310: =Revenue!B311 -> Oct | C310: =A310&"|"&B310 -> P0026|Oct | D310: =Revenue!J311 -> 935.0244 | E310: =_xlfn.XLOOKUP($C310,ExpensesTbl[Key],ExpensesTbl[Total Operating Expenses]) -> 849.64 | F310: =D310-E310 -> 85.3844 | G310: =_xlfn.XLOOKUP($A310,PropertiesTbl[Property ID],PropertiesTbl[Property Name]) -> Frost Cabin
A311: =Revenue!A312 -> P0026 | B311: =Revenue!B312 -> Nov | C311: =A311&"|"&B311 -> P0026|Nov | D311: =Revenue!J312 -> 758.659 | E311: =_xlfn.XLOOKUP($C311,ExpensesTbl[Key],ExpensesTbl[Total Operating Expenses]) -> 586.74 | F311: =D311-E311 -> 171.919 | G311: =_xlfn.XLOOKUP($A311,PropertiesTbl[Property ID],PropertiesTbl[Property Name]) -> Frost Cabin
A312: =Revenue!A313 -> P0026 | B312: =Revenue!B313 -> Dec | C312: =A312&"|"&B312 -> P0026|Dec | D312: =Revenue!J313 -> 2849.8762 | E312: =_xlfn.XLOOKUP($C312,ExpensesTbl[Key],ExpensesTbl[Total Operating Expenses]) -> 1072.78 | F312: =D312-E312 -> 1777.0962 | G312: =_xlfn.XLOOKUP($A312,PropertiesTbl[Property ID],PropertiesTbl[Property Name]) -> Frost Cabin
A313: =Revenue!A314 -> P0026 | B313: =Revenue!B314 -> Jan | C313: =A313&"|"&B313 -> P0026|Jan | D313: =Revenue!J314 -> 2955.936 | E313: =_xlfn.XLOOKUP($C313,ExpensesTbl[Key],ExpensesTbl[Total Operating Expenses]) -> 865.68 | F313: =D313-E313 -> 2090.256 | G313: =_xlfn.XLOOKUP($A313,PropertiesTbl[Property ID],PropertiesTbl[Property Name]) -> Frost Cabin
A314: =Revenue!A315 -> P0026 | B314: =Revenue!B315 -> Feb | C314: =A314&"|"&B314 -> P0026|Feb | D314: =Revenue!J315 -> 2184.872 | E314: =_xlfn.XLOOKUP($C314,ExpensesTbl[Key],ExpensesTbl[Total Operating Expenses]) -> 770.73 | F314: =D314-E314 -> 1414.142 | G314: =_xlfn.XLOOKUP($A314,PropertiesTbl[Property ID],PropertiesTbl[Property Name]) -> Frost Cabin
A315: =Revenue!A316 -> P0026 | B315: =Revenue!B316 -> Mar | C315: =A315&"|"&B315 -> P0026|Mar | D315: =Revenue!J316 -> 1990.484 | E315: =_xlfn.XLOOKUP($C315,ExpensesTbl[Key],ExpensesTbl[Total Operating Expenses]) -> 790.65 | F315: =D315-E315 -> 1199.834 | G315: =_xlfn.XLOOKUP($A315,PropertiesTbl[Property ID],PropertiesTbl[Property Name]) -> Frost Cabin
... A3603: =Revenue!A3604 -> P0300 | B3603: =Revenue!B3604 -> Mar | C3603: =A3603&"|"&B3603 -> P0300|Mar | D3603: =Revenue!J3604 -> 3881.5196 | E3603: =_xlfn.XLOOKUP($C3603,ExpensesTbl[Key],ExpensesTbl[Total Operating Expenses]) -> 1159.23 | F3603: =D3603-E3603 -> 2722.2896 | G3603: =_xlfn.XLOOKUP($A3603,PropertiesTbl[Property ID],PropertiesTbl[Property Name]) -> Trailside Cottage
...
